Loading checkpoint shards:   0%|          | 0/2 [00:00<?, ?it/s]Loading checkpoint shards:  50%|█████     | 1/2 [00:01<00:01,  1.57s/it]Loading checkpoint shards: 100%|██████████| 2/2 [00:02<00:00,  1.13s/it]Loading checkpoint shards: 100%|██████████| 2/2 [00:02<00:00,  1.20s/it]
Loading checkpoint shards:   0%|          | 0/4 [00:00<?, ?it/s]Loading checkpoint shards:  25%|██▌       | 1/4 [00:01<00:04,  1.51s/it]Loading checkpoint shards:  50%|█████     | 2/4 [00:03<00:03,  1.85s/it]Loading checkpoint shards:  75%|███████▌  | 3/4 [00:05<00:01,  1.71s/it]Loading checkpoint shards: 100%|██████████| 4/4 [00:05<00:00,  1.18s/it]Loading checkpoint shards: 100%|██████████| 4/4 [00:05<00:00,  1.38s/it]
Special tokens have been added in the vocabulary, make sure the associated word embeddings are fine-tuned or trained.
Loading checkpoint shards:   0%|          | 0/3 [00:00<?, ?it/s]Loading checkpoint shards:  33%|███▎      | 1/3 [00:01<00:03,  1.58s/it]Loading checkpoint shards:  67%|██████▋   | 2/3 [00:02<00:01,  1.15s/it]Loading checkpoint shards: 100%|██████████| 3/3 [00:03<00:00,  1.03it/s]Loading checkpoint shards: 100%|██████████| 3/3 [00:03<00:00,  1.06s/it]
Special tokens have been added in the vocabulary, make sure the associated word embeddings are fine-tuned or trained.
Loading checkpoint shards:   0%|          | 0/6 [00:00<?, ?it/s]Loading checkpoint shards:  17%|█▋        | 1/6 [00:01<00:07,  1.53s/it]Loading checkpoint shards:  33%|███▎      | 2/6 [00:02<00:05,  1.41s/it]Loading checkpoint shards:  50%|█████     | 3/6 [00:04<00:04,  1.35s/it]Loading checkpoint shards:  67%|██████▋   | 4/6 [00:05<00:02,  1.33s/it]Loading checkpoint shards:  83%|████████▎ | 5/6 [00:06<00:01,  1.29s/it]Loading checkpoint shards: 100%|██████████| 6/6 [00:07<00:00,  1.04s/it]Loading checkpoint shards: 100%|██████████| 6/6 [00:07<00:00,  1.20s/it]
Traceback (most recent call last):
  File "/nfs/home/ernstd/miniconda3/envs/transformer/lib/python3.12/site-packages/transformers/utils/hub.py", line 385, in cached_file
    resolved_file = hf_hub_download(
                    ^^^^^^^^^^^^^^^^
  File "/nfs/home/ernstd/miniconda3/envs/transformer/lib/python3.12/site-packages/huggingface_hub/utils/_validators.py", line 110, in _inner_fn
    validate_repo_id(arg_value)
  File "/nfs/home/ernstd/miniconda3/envs/transformer/lib/python3.12/site-packages/huggingface_hub/utils/_validators.py", line 158, in validate_repo_id
    raise HFValidationError(
huggingface_hub.utils._validators.HFValidationError: Repo id must be in the form 'repo_name' or 'namespace/repo_name': '/nfs/home/ernstd/models/llava-v1.6-mistral-7b-hf/'. Use `repo_type` argument if needed.

The above exception was the direct cause of the following exception:

Traceback (most recent call last):
  File "/nfs/home/ernstd/masterthesis_scripts/./model_scripts/llava.py", line 135, in <module>
    run(args, answerFile)
  File "/nfs/home/ernstd/masterthesis_scripts/./model_scripts/llava.py", line 106, in run
    llava = llavaInstance(args)
            ^^^^^^^^^^^^^^^^^^^
  File "/nfs/home/ernstd/masterthesis_scripts/./model_scripts/llava.py", line 37, in __init__
    self.processor = AutoProcessor.from_pretrained(args.model_path)
                     ^^^^^^^^^^^^^^^^^^^^^^^^^^^^^^^^^^^^^^^^^^^^^^
  File "/nfs/home/ernstd/miniconda3/envs/transformer/lib/python3.12/site-packages/transformers/models/auto/processing_auto.py", line 239, in from_pretrained
    processor_config_file = get_file_from_repo(
                            ^^^^^^^^^^^^^^^^^^^
  File "/nfs/home/ernstd/miniconda3/envs/transformer/lib/python3.12/site-packages/transformers/utils/hub.py", line 537, in get_file_from_repo
    return cached_file(
           ^^^^^^^^^^^^
  File "/nfs/home/ernstd/miniconda3/envs/transformer/lib/python3.12/site-packages/transformers/utils/hub.py", line 450, in cached_file
    raise EnvironmentError(
OSError: Incorrect path_or_model_id: '/nfs/home/ernstd/models/llava-v1.6-mistral-7b-hf/'. Please provide either the path to a local folder or the repo_id of a model on the Hub.
Traceback (most recent call last):
  File "/nfs/home/ernstd/masterthesis_scripts/./experiments/2_entity_verification/scripts/tamperednews/analyze_answers.py", line 100, in <module>
    computeAnswer(args)
  File "/nfs/home/ernstd/masterthesis_scripts/./experiments/2_entity_verification/scripts/tamperednews/analyze_answers.py", line 31, in computeAnswer
    with open(f"./output/model_answers/{modelname}.jsonl", 'r') as file:
         ^^^^^^^^^^^^^^^^^^^^^^^^^^^^^^^^^^^^^^^^^^^^^^^^^^^^^^
FileNotFoundError: [Errno 2] No such file or directory: './output/model_answers/EV-tamperednews-llava_1_6_7b_answers.jsonl'
Traceback (most recent call last):
  File "/nfs/home/ernstd/masterthesis_scripts/./experiments/2_entity_verification/scripts/tamperednews/printResultTable.py", line 58, in <module>
    printResults(args)
  File "/nfs/home/ernstd/masterthesis_scripts/./experiments/2_entity_verification/scripts/tamperednews/printResultTable.py", line 34, in printResults
    with open(f"./output/statistics/{modelname}.csv", 'r') as file:
         ^^^^^^^^^^^^^^^^^^^^^^^^^^^^^^^^^^^^^^^^^^^^^^^^^
FileNotFoundError: [Errno 2] No such file or directory: './output/statistics/EV-tamperednews-llava_1_6_7b_answers.csv'
